Workbook

Sheet DASHBOARD
B2: 120-DAY AI/ML ENGINEER STUDY TRACKER
B5: OVERALL METRICS | F5: SUBJECT PROGRESS
B6: Total Topics | C6: =COUNTA('DAILY STUDY PLAN'!G2:G2000) | F6: Subject | G6: Total | H6: Completed | I6: Progress %
B7: Completed Topics | C7: =COUNTIF('DAILY STUDY PLAN'!T2:T2000, "COMPLETED") | F7: Python | G7: =COUNTIF('DAILY STUDY PLAN'!F:F, "Python") | H7: =COUNTIFS('DAILY STUDY PLAN'!F:F, "Python", 'DAILY STUDY PLAN'!T:T, "COMPLETED") | I7: =IFERROR(H7/G7, 0)
B8: Remaining Topics | C8: =B6-B7 | F8: NumPy | G8: =COUNTIF('DAILY STUDY PLAN'!F:F, "NumPy") | H8: =COUNTIFS('DAILY STUDY PLAN'!F:F, "NumPy", 'DAILY STUDY PLAN'!T:T, "COMPLETED") | I8: =IFERROR(H8/G8, 0)
B9: Overall Completion % | C9: =IFERROR(B7/B6, 0) | F9: Pandas | G9: =COUNTIF('DAILY STUDY PLAN'!F:F, "Pandas") | H9: =COUNTIFS('DAILY STUDY PLAN'!F:F, "Pandas", 'DAILY STUDY PLAN'!T:T, "COMPLETED") | I9: =IFERROR(H9/G9, 0)
B10: Total Days | C10: 120 | F10: SQL | G10: =COUNTIF('DAILY STUDY PLAN'!F:F, "SQL") | H10: =COUNTIFS('DAILY STUDY PLAN'!F:F, "SQL", 'DAILY STUDY PLAN'!T:T, "COMPLETED") | I10: =IFERROR(H10/G10, 0)
B11: Mock Interviews | C11: =COUNTIF('DAILY STUDY PLAN'!H2:H2000, "*Mock*") | F11: Math | G11: =COUNTIF('DAILY STUDY PLAN'!F:F, "Math") | H11: =COUNTIFS('DAILY STUDY PLAN'!F:F, "Math", 'DAILY STUDY PLAN'!T:T, "COMPLETED") | I11: =IFERROR(H11/G11, 0)
F12: Machine Learning | G12: =COUNTIF('DAILY STUDY PLAN'!F:F, "Machine Learning") | H12: =COUNTIFS('DAILY STUDY PLAN'!F:F, "Machine Learning", 'DAILY STUDY PLAN'!T:T, "COMPLETED") | I12: =IFERROR(H12/G12, 0)
F13: Deep Learning | G13: =COUNTIF('DAILY STUDY PLAN'!F:F, "Deep Learning") | H13: =COUNTIFS('DAILY STUDY PLAN'!F:F, "Deep Learning", 'DAILY STUDY PLAN'!T:T, "COMPLETED") | I13: =IFERROR(H13/G13, 0)
F14: PyTorch | G14: =COUNTIF('DAILY STUDY PLAN'!F:F, "PyTorch") | H14: =COUNTIFS('DAILY STUDY PLAN'!F:F, "PyTorch", 'DAILY STUDY PLAN'!T:T, "COMPLETED") | I14: =IFERROR(H14/G14, 0)
F15: TensorFlow | G15: =COUNTIF('DAILY STUDY PLAN'!F:F, "TensorFlow") | H15: =COUNTIFS('DAILY STUDY PLAN'!F:F, "TensorFlow", 'DAILY STUDY PLAN'!T:T, "COMPLETED") | I15: =IFERROR(H15/G15, 0)
F16: Computer Vision | G16: =COUNTIF('DAILY STUDY PLAN'!F:F, "Computer Vision") | H16: =COUNTIFS('DAILY STUDY PLAN'!F:F, "Computer Vision", 'DAILY STUDY PLAN'!T:T, "COMPLETED") | I16: =IFERROR(H16/G16, 0)
F17: NLP | G17: =COUNTIF('DAILY STUDY PLAN'!F:F, "NLP") | H17: =COUNTIFS('DAILY STUDY PLAN'!F:F, "NLP", 'DAILY STUDY PLAN'!T:T, "COMPLETED") | I17: =IFERROR(H17/G17, 0)
F18: Generative AI | G18: =COUNTIF('DAILY STUDY PLAN'!F:F, "Generative AI") | H18: =COUNTIFS('DAILY STUDY PLAN'!F:F, "Generative AI", 'DAILY STUDY PLAN'!T:T, "COMPLETED") | I18: =IFERROR(H18/G18, 0)
F19: Prompt Engineering | G19: =COUNTIF('DAILY STUDY PLAN'!F:F, "Prompt Engineering") | H19: =COUNTIFS('DAILY STUDY PLAN'!F:F, "Prompt Engineering", 'DAILY STUDY PLAN'!T:T, "COMPLETED") | I19: =IFERROR(H19/G19, 0)
F20: Transformers | G20: =COUNTIF('DAILY STUDY PLAN'!F:F, "Transformers") | H20: =COUNTIFS('DAILY STUDY PLAN'!F:F, "Transformers", 'DAILY STUDY PLAN'!T:T, "COMPLETED") | I20: =IFERROR(H20/G20, 0)
F21: Hugging Face | G21: =COUNTIF('DAILY STUDY PLAN'!F:F, "Hugging Face") | H21: =COUNTIFS('DAILY STUDY PLAN'!F:F, "Hugging Face", 'DAILY STUDY PLAN'!T:T, "COMPLETED") | I21: =IFERROR(H21/G21, 0)
F22: Fine-Tuning | G22: =COUNTIF('DAILY STUDY PLAN'!F:F, "Fine-Tuning") | H22: =COUNTIFS('DAILY STUDY PLAN'!F:F, "Fine-Tuning", 'DAILY STUDY PLAN'!T:T, "COMPLETED") | I22: =IFERROR(H22/G22, 0)
F23: RAG | G23: =COUNTIF('DAILY STUDY PLAN'!F:F, "RAG") | H23: =COUNTIFS('DAILY STUDY PLAN'!F:F, "RAG", 'DAILY STUDY PLAN'!T:T, "COMPLETED") | I23: =IFERROR(H23/G23, 0)
F24: Vector DB | G24: =COUNTIF('DAILY STUDY PLAN'!F:F, "Vector DB") | H24: =COUNTIFS('DAILY STUDY PLAN'!F:F, "Vector DB", 'DAILY STUDY PLAN'!T:T, "COMPLETED") | I24: =IFERROR(H24/G24, 0)
F25: LangChain | G25: =COUNTIF('DAILY STUDY PLAN'!F:F, "LangChain") | H25: =COUNTIFS('DAILY STUDY PLAN'!F:F, "LangChain", 'DAILY STUDY PLAN'!T:T, "COMPLETED") | I25: =IFERROR(H25/G25, 0)
F26: LangGraph | G26: =COUNTIF('DAILY STUDY PLAN'!F:F, "LangGraph") | H26: =COUNTIFS('DAILY STUDY PLAN'!F:F, "LangGraph", 'DAILY STUDY PLAN'!T:T, "COMPLETED") | I26: =IFERROR(H26/G26, 0)
F27: FastAPI | G27: =COUNTIF('DAILY STUDY PLAN'!F:F, "FastAPI") | H27: =COUNTIFS('DAILY STUDY PLAN'!F:F, "FastAPI", 'DAILY STUDY PLAN'!T:T, "COMPLETED") | I27: =IFERROR(H27/G27, 0)
F28: Git | G28: =COUNTIF('DAILY STUDY PLAN'!F:F, "Git") | H28: =COUNTIFS('DAILY STUDY PLAN'!F:F, "Git", 'DAILY STUDY PLAN'!T:T, "COMPLETED") | I28: =IFERROR(H28/G28, 0)
F29: Docker | G29: =COUNTIF('DAILY STUDY PLAN'!F:F, "Docker") | H29: =COUNTIFS('DAILY STUDY PLAN'!F:F, "Docker", 'DAILY STUDY PLAN'!T:T, "COMPLETED") | I29: =IFERROR(H29/G29, 0)
F30: DSA | G30: =COUNTIF('DAILY STUDY PLAN'!F:F, "DSA") | H30: =COUNTIFS('DAILY STUDY PLAN'!F:F, "DSA", 'DAILY STUDY PLAN'!T:T, "COMPLETED") | I30: =IFERROR(H30/G30, 0)
F31: Project | G31: =COUNTIF('DAILY STUDY PLAN'!F:F, "Project") | H31: =COUNTIFS('DAILY STUDY PLAN'!F:F, "Project", 'DAILY STUDY PLAN'!T:T, "COMPLETED") | I31: =IFERROR(H31/G31, 0)

Sheet DAILY TIMETABLE
A1: Time | B1: Activity | C1: Duration | D1: Description
A2: 10:00 AM – 10:30 AM | B2: English Practice | C2: 30 min | D2: Reading aloud, Technical speaking, Interview speaking
A3: 10:30 AM – 12:00 PM | B3: Main Technical Study | C3: 90 min | D3: Deep focus on primary daily topics
A4: 12:00 PM – 12:15 PM | B4: Short Break | C4: 15 min | D4: Rest eyes, stretch
A5: 12:15 PM – 2:00 PM | B5: Coding / Practice | C5: 105 min | D5: Hands-on implementation of studied topics
A6: 2:00 PM – 3:00 PM | B6: Lunch + Rest | C6: 60 min | D6: Meal and mental recharge
A7: 3:00 PM – 5:00 PM | B7: Project / Hands-On | C7: 120 min | D7: Applying concepts to main portfolio projects
A8: 5:00 PM – 5:30 PM | B8: Break | C8: 30 min | D8: Evening walk or tea
A9: 5:30 PM – 6:30 PM | B9: DSA / SQL / Revision | C9: 60 min | D9: Algorithm practice, queries, or reviewing previous concepts
A10: 6:30 PM – 7:30 PM | B10: Interview Preparation | C10: 60 min | D10: Mock answers, theory review, behavioral questions
A11: 7:30 PM – 8:30 PM | B11: Dinner | C11: 60 min | D11: Dinner time
A12: 8:30 PM – 9:30 PM | B12: Job Applications | C12: 60 min | D12: Updating resume, tailoring cover letters, applying to targets
A13: 9:30 PM – 10:00 PM | B13: Revision & Planning | C13: 30 min | D13: Quick recap of the day and setting up for tomorrow

Sheet DAILY STUDY PLAN
A1: Day | B1: Date | C1: Week | D1: Month | E1: Phase | F1: Subject | G1: Topic | H1: Subtopic | I1: What to Learn | J1: Study Time | K1: Practice Time | L1: Practice Task | M1: Interview Time | N1: Interview Question | O1: English Time | P1: English Practice | Q1: Project Work | R1: Job Application Target | S1: Completion Checkbox | T1: Status | U1: Notes
A2: 1 | B2: 2026-08-31 | C2: 1 | D2: 1 | E2: Month 1 | F2: Python | G2: Setup | H2: Python installation | I2: Master Python installation | J2: 45 min | K2: 45 min | L2: Code/Implement Python installation | M2: 15 min | N2: Why is Python installation important in a project? | O2: 15 min | P2: Explain how you setup Python installation. | Q2: Build/Refine code | R2: 5 | S2: ☐ Not Started | T2: =IF(S2="☑ Completed", "COMPLETED", "NOT STARTED") | U2: Review Notes for Day 1
A3: 1 | B3: 2026-08-31 | C3: 1 | D3: 1 | E3: Month 1 | F3: Python | G3: Setup | H3: VS Code setup | I3: Master VS Code setup | J3: 30 min | K3: 30 min | L3: Code/Implement VS Code setup | M3: 15 min | N3: Why is VS Code setup important in a project? | O3: 15 min | P3: Explain how you setup VS Code setup. | Q3: Build/Refine code | R3: - | S3: ☐ Not Started | T3: =IF(S3="☑ Completed", "COMPLETED", "NOT STARTED") | U3: Review Notes for Day 1
A4: 1 | B4: 2026-08-31 | C4: 1 | D4: 1 | E4: Month 1 | F4: Python | G4: Setup | H4: Virtual environment | I4: Master Virtual environment | J4: 30 min | K4: 30 min | L4: Code/Implement Virtual environment | M4: 15 min | N4: Why is Virtual environment important in a project? | O4: 15 min | P4: Explain how you setup Virtual environment. | Q4: Build/Refine code | R4: - | S4: ☐ Not Started | T4: =IF(S4="☑ Completed", "COMPLETED", "NOT STARTED") | U4: Review Notes for Day 1
A5: 1 | B5: 2026-08-31 | C5: 1 | D5: 1 | E5: Month 1 | F5: Python | G5: Setup | H5: pip | I5: Master pip | J5: 30 min | K5: 30 min | L5: Code/Implement pip | M5: 15 min | N5: Why is pip important in a project? | O5: 15 min | P5: Explain how you setup pip. | Q5: Build/Refine code | R5: - | S5: ☐ Not Started | T5: =IF(S5="☑ Completed", "COMPLETED", "NOT STARTED") | U5: Review Notes for Day 1
A6: 1 | B6: 2026-08-31 | C6: 1 | D6: 1 | E6: Month 1 | F6: Python | G6: Setup | H6: requirements.txt | I6: Master requirements.txt | J6: 30 min | K6: 30 min | L6: Code/Implement requirements.txt | M6: 15 min | N6: Why is requirements.txt important in a project? | O6: 15 min | P6: Explain how you setup requirements.txt. | Q6: Build/Refine code | R6: - | S6: ☐ Not Started | T6: =IF(S6="☑ Completed", "COMPLETED", "NOT STARTED") | U6: Review Notes for Day 1
A7: 2 | B7: 2026-09-01 | C7: 1 | D7: 1 | E7: Month 1 | F7: Python | G7: Basics | H7: Python syntax | I7: Master Python syntax | J7: 45 min | K7: 45 min | L7: Code/Implement Python syntax | M7: 15 min | N7: What is the difference between various types in Python? (focus on Python syntax) | O7: 15 min | P7: Explain what Python syntax means to a non-technical person. | Q7: Build/Refine code | R7: 5 | S7: ☐ Not Started | T7: =IF(S7="☑ Completed", "COMPLETED", "NOT STARTED") | U7: Review Notes for Day 2
A8: 2 | B8: 2026-09-01 | C8: 1 | D8: 1 | E8: Month 1 | F8: Python | G8: Basics | H8: Variables | I8: Master Variables | J8: 30 min | K8: 30 min | L8: Code/Implement Variables | M8: 15 min | N8: What is the difference between various types in Python? (focus on Variables) | O8: 15 min | P8: Explain what Variables means to a non-technical person. | Q8: Build/Refine code | R8: - | S8: ☐ Not Started | T8: =IF(S8="☑ Completed", "COMPLETED", "NOT STARTED") | U8: Review Notes for Day 2
A9: 2 | B9: 2026-09-01 | C9: 1 | D9: 1 | E9: Month 1 | F9: Python | G9: Basics | H9: int | I9: Master int | J9: 30 min | K9: 30 min | L9: Code/Implement int | M9: 15 min | N9: What is the difference between various types in Python? (focus on int) | O9: 15 min | P9: Explain what int means to a non-technical person. | Q9: Build/Refine code | R9: - | S9: ☐ Not Started | T9: =IF(S9="☑ Completed", "COMPLETED", "NOT STARTED") | U9: Review Notes for Day 2
A10: 2 | B10: 2026-09-01 | C10: 1 | D10: 1 | E10: Month 1 | F10: Python | G10: Basics | H10: float | I10: Master float | J10: 30 min | K10: 30 min | L10: Code/Implement float | M10: 15 min | N10: What is the difference between various types in Python? (focus on float) | O10: 15 min | P10: Explain what float means to a non-technical person. | Q10: Build/Refine code | R10: - | S10: ☐ Not Started | T10: =IF(S10="☑ Completed", "COMPLETED", "NOT STARTED") | U10: Review Notes for Day 2
A11: 2 | B11: 2026-09-01 | C11: 1 | D11: 1 | E11: Month 1 | F11: Python | G11: Basics | H11: string | I11: Master string | J11: 30 min | K11: 30 min | L11: Code/Implement string | M11: 15 min | N11: What is the difference between various types in Python? (focus on string) | O11: 15 min | P11: Explain what string means to a non-technical person. | Q11: Build/Refine code | R11: - | S11: ☐ Not Started | T11: =IF(S11="☑ Completed", "COMPLETED", "NOT STARTED") | U11: Review Notes for Day 2
A12: 3 | B12: 2026-09-02 | C12: 1 | D12: 1 | E12: Month 1 | F12: Python | G12: Basics | H12: boolean | I12: Master boolean | J12: 45 min | K12: 45 min | L12: Code/Implement boolean | M12: 15 min | N12: What is the difference between various types in Python? (focus on boolean) | O12: 15 min | P12: Explain what boolean means to a non-technical person. | Q12: Build/Refine code | R12: 5 | S12: ☐ Not Started | T12: =IF(S12="☑ Completed", "COMPLETED", "NOT STARTED") | U12: Review Notes for Day 3
A13: 3 | B13: 2026-09-02 | C13: 1 | D13: 1 | E13: Month 1 | F13: Python | G13: Basics | H13: None | I13: Master None | J13: 30 min | K13: 30 min | L13: Code/Implement None | M13: 15 min | N13: What is the difference between various types in Python? (focus on None) | O13: 15 min | P13: Explain what None means to a non-technical person. | Q13: Build/Refine code | R13: - | S13: ☐ Not Started | T13: =IF(S13="☑ Completed", "COMPLETED", "NOT STARTED") | U13: Review Notes for Day 3
A14: 3 | B14: 2026-09-02 | C14: 1 | D14: 1 | E14: Month 1 | F14: Python | G14: Basics | H14: Type conversion | I14: Master Type conversion | J14: 30 min | K14: 30 min | L14: Code/Implement Type conversion | M14: 15 min | N14: What is the difference between various types in Python? (focus on Type conversion) | O14: 15 min | P14: Explain what Type conversion means to a non-technical person. | Q14: Build/Refine code | R14: - | S14: ☐ Not Started | T14: =IF(S14="☑ Completed", "COMPLETED", "NOT STARTED") | U14: Review Notes for Day 3
A15: 3 | B15: 2026-09-02 | C15: 1 | D15: 1 | E15: Month 1 | F15: Python | G15: Operators | H15: Arithmetic | I15: Master Arithmetic | J15: 30 min | K15: 30 min | L15: Code/Implement Arithmetic | M15: 15 min | N15: How do Arithmetic operators work in Python? | O15: 15 min | P15: Give a real life example of using Arithmetic. | Q15: Build/Refine code | R15: - | S15: ☐ Not Started | T15: =IF(S15="☑ Completed", "COMPLETED", "NOT STARTED") | U15: Review Notes for Day 3
A16: 3 | B16: 2026-09-02 | C16: 1 | D16: 1 | E16: Month 1 | F16: Python | G16: Operators | H16: Comparison | I16: Master Comparison | J16: 30 min | K16: 30 min | L16: Code/Implement Comparison | M16: 15 min | N16: How do Comparison operators work in Python? | O16: 15 min | P16: Give a real life example of using Comparison. | Q16: Build/Refine code | R16: - | S16: ☐ Not Started | T16: =IF(S16="☑ Completed", "COMPLETED", "NOT STARTED") | U16: Review Notes for Day 3
A17: 4 | B17: 2026-09-03 | C17: 1 | D17: 1 | E17: Month 1 | F17: Python | G17: Operators | H17: Logical | I17: Master Logical | J17: 45 min | K17: 45 min | L17: Code/Implement Logical | M17: 15 min | N17: How do Logical operators work in Python? | O17: 15 min | P17: Give a real life example of using Logical. | Q17: Build/Refine code | R17: 5 | S17: ☐ Not Started | T17: =IF(S17="☑ Completed", "COMPLETED", "NOT STARTED") | U17: Review Notes for Day 4
A18: 4 | B18: 2026-09-03 | C18: 1 | D18: 1 | E18: Month 1 | F18: Python | G18: Operators | H18: Assignment | I18: Master Assignment | J18: 30 min | K18: 30 min | L18: Code/Implement Assignment | M18: 15 min | N18: How do Assignment operators work in Python? | O18: 15 min | P18: Give a real life example of using Assignment. | Q18: Build/Refine code | R18: - | S18: ☐ Not Started | T18: =IF(S18="☑ Completed", "COMPLETED", "NOT STARTED") | U18: Review Notes for Day 4
A19: 4 | B19: 2026-09-03 | C19: 1 | D19: 1 | E19: Month 1 | F19: Python | G19: Operators | H19: Membership | I19: Master Membership | J19: 30 min | K19: 30 min | L19: Code/Implement Membership | M19: 15 min | N19: How do Membership operators work in Python? | O19: 15 min | P19: Give a real life example of using Membership. | Q19: Build/Refine code | R19: - | S19: ☐ Not Started | T19: =IF(S19="☑ Completed", "COMPLETED", "NOT STARTED") | U19: Review Notes for Day 4
A20: 4 | B20: 2026-09-03 | C20: 1 | D20: 1 | E20: Month 1 | F20: Python | G20: Operators | H20: Identity | I20: Master Identity | J20: 30 min | K20: 30 min | L20: Code/Implement Identity | M20: 15 min | N20: How do Identity operators work in Python? | O20: 15 min | P20: Give a real life example of using Identity. | Q20: Build/Refine code | R20: - | S20: ☐ Not Started | T20: =IF(S20="☑ Completed", "COMPLETED", "NOT STARTED") | U20: Review Notes for Day 4
A21: 4 | B21: 2026-09-03 | C21: 1 | D21: 1 | E21: Month 1 | F21: Python | G21: Data Structures | H21: Strings | I21: Master Strings | J21: 30 min | K21: 30 min | L21: Code/Implement Strings | M21: 15 min | N21: What is the time complexity of common Strings operations? | O21: 15 min | P21: Compare Strings with another data structure in English. | Q21: Build/Refine code | R21: - | S21: ☐ Not Started | T21: =IF(S21="☑ Completed", "COMPLETED", "NOT STARTED") | U21: Review Notes for Day 4
A22: 5 | B22: 2026-09-04 | C22: 1 | D22: 1 | E22: Month 1 | F22: Python | G22: Data Structures | H22: String indexing | I22: Master String indexing | J22: 45 min | K22: 45 min | L22: Code/Implement String indexing | M22: 15 min | N22: What is the time complexity of common String indexing operations? | O22: 15 min | P22: Compare String indexing with another data structure in English. | Q22: Build/Refine code | R22: 5 | S22: ☐ Not Started | T22: =IF(S22="☑ Completed", "COMPLETED", "NOT STARTED") | U22: Review Notes for Day 5
A23: 5 | B23: 2026-09-04 | C23: 1 | D23: 1 | E23: Month 1 | F23: Python | G23: Data Structures | H23: String slicing | I23: Master String slicing | J23: 30 min | K23: 30 min | L23: Code/Implement String slicing | M23: 15 min | N23: What is the time complexity of common String slicing operations? | O23: 15 min | P23: Compare String slicing with another data structure in English. | Q23: Build/Refine code | R23: - | S23: ☐ Not Started | T23: =IF(S23="☑ Completed", "COMPLETED", "NOT STARTED") | U23: Review Notes for Day 5
A24: 5 | B24: 2026-09-04 | C24: 1 | D24: 1 | E24: Month 1 | F24: Python | G24: Data Structures | H24: String methods | I24: Master String methods | J24: 30 min | K24: 30 min | L24: Code/Implement String methods | M24: 15 min | N24: What is the time complexity of common String methods operations? | O24: 15 min | P24: Compare String methods with another data structure in English. | Q24: Build/Refine code | R24: - | S24: ☐ Not Started | T24: =IF(S24="☑ Completed", "COMPLETED", "NOT STARTED") | U24: Review Notes for Day 5
A25: 5 | B25: 2026-09-04 | C25: 1 | D25: 1 | E25: Month 1 | F25: Python | G25: Data Structures | H25: Lists | I25: Master Lists | J25: 30 min | K25: 30 min | L25: Code/Implement Lists | M25: 15 min | N25: What is the time complexity of common Lists operations? | O25: 15 min | P25: Compare Lists with another data structure in English. | Q25: Build/Refine code | R25: - | S25: ☐ Not Started | T25: =IF(S25="☑ Completed", "COMPLETED", "NOT STARTED") | U25: Review Notes for Day 5
A26: 5 | B26: 2026-09-04 | C26: 1 | D26: 1 | E26: Month 1 | F26: Python | G26: Data Structures | H26: List indexing | I26: Master List indexing | J26: 30 min | K26: 30 min | L26: Code/Implement List indexing | M26: 15 min | N26: What is the time complexity of common List indexing operations? | O26: 15 min | P26: Compare List indexing with another data structure in English. | Q26: Build/Refine code | R26: - | S26: ☐ Not Started | T26: =IF(S26="☑ Completed", "COMPLETED", "NOT STARTED") | U26: Review Notes for Day 5
A27: 6 | B27: 2026-09-05 | C27: 1 | D27: 1 | E27: Month 1 | F27: Python | G27: Data Structures | H27: List slicing | I27: Master List slicing | J27: 45 min | K27: 45 min | L27: Code/Implement List slicing | M27: 15 min | N27: What is the time complexity of common List slicing operations? | O27: 15 min | P27: Compare List slicing with another data structure in English. | Q27: Build/Refine code | R27: 5 | S27: ☐ Not Started | T27: =IF(S27="☑ Completed", "COMPLETED", "NOT STARTED") | U27: Review Notes for Day 6
A28: 6 | B28: 2026-09-05 | C28: 1 | D28: 1 | E28: Month 1 | F28: Python | G28: Data Structures | H28: List methods | I28: Master List methods | J28: 30 min | K28: 30 min | L28: Code/Implement List methods | M28: 15 min | N28: What is the time complexity of common List methods operations? | O28: 15 min | P28: Compare List methods with another data structure in English. | Q28: Build/Refine code | R28: - | S28: ☐ Not Started | T28: =IF(S28="☑ Completed", "COMPLETED", "NOT STARTED") | U28: Review Notes for Day 6
A29: 6 | B29: 2026-09-05 | C29: 1 | D29: 1 | E29: Month 1 | F29: Python | G29: Data Structures | H29: Tuples | I29: Master Tuples | J29: 30 min | K29: 30 min | L29: Code/Implement Tuples | M29: 15 min | N29: What is the time complexity of common Tuples operations? | O29: 15 min | P29: Compare Tuples with another data structure in English. | Q29: Build/Refine code | R29: - | S29: ☐ Not Started | T29: =IF(S29="☑ Completed", "COMPLETED", "NOT STARTED") | U29: Review Notes for Day 6
A30: 6 | B30: 2026-09-05 | C30: 1 | D30: 1 | E30: Month 1 | F30: Python | G30: Data Structures | H30: Tuple methods | I30: Master Tuple methods | J30: 30 min | K30: 30 min | L30: Code/Implement Tuple methods | M30: 15 min | N30: What is the time complexity of common Tuple methods operations? | O30: 15 min | P30: Compare Tuple methods with another data structure in English. | Q30: Build/Refine code | R30: - | S30: ☐ Not Started | T30: =IF(S30="☑ Completed", "COMPLETED", "NOT STARTED") | U30: Review Notes for Day 6
A31: 6 | B31: 2026-09-05 | C31: 1 | D31: 1 | E31: Month 1 | F31: Python | G31: Data Structures | H31: Sets | I31: Master Sets | J31: 30 min | K31: 30 min | L31: Code/Implement Sets | M31: 15 min | N31: What is the time complexity of common Sets operations? | O31: 15 min | P31: Compare Sets with another data structure in English. | Q31: Build/Refine code | R31: - | S31: ☐ Not Started | T31: =IF(S31="☑ Completed", "COMPLETED", "NOT STARTED") | U31: Review Notes for Day 6
A32: 7 | B32: 2026-09-06 | C32: 1 | D32: 1 | E32: Month 1 | F32: Python | G32: Data Structures | H32: Set operations | I32: Master Set operations | J32: 45 min | K32: 45 min | L32: Code/Implement Set operations | M32: 15 min | N32: What is the time complexity of common Set operations operations? | O32: 15 min | P32: Compare Set operations with another data structure in English. | Q32: Build/Refine code | R32: 5 | S32: ☐ Not Started | T32: =IF(S32="☑ Completed", "COMPLETED", "NOT STARTED") | U32: Review Notes for Day 7
A33: 7 | B33: 2026-09-06 | C33: 1 | D33: 1 | E33: Month 1 | F33: Python | G33: Data Structures | H33: Dictionaries | I33: Master Dictionaries | J33: 30 min | K33: 30 min | L33: Code/Implement Dictionaries | M33: 15 min | N33: What is the time complexity of common Dictionaries operations? | O33: 15 min | P33: Compare Dictionaries with another data structure in English. | Q33: Build/Refine code | R33: - | S33: ☐ Not Started | T33: =IF(S33="☑ Completed", "COMPLETED", "NOT STARTED") | U33: Review Notes for Day 7
A34: 7 | B34: 2026-09-06 | C34: 1 | D34: 1 | E34: Month 1 | F34: Python | G34: Data Structures | H34: Dictionary methods | I34: Master Dictionary methods | J34: 30 min | K34: 30 min | L34: Code/Implement Dictionary methods | M34: 15 min | N34: What is the time complexity of common Dictionary methods operations? | O34: 15 min | P34: Compare Dictionary methods with another data structure in English. | Q34: Build/Refine code | R34: - | S34: ☐ Not Started | T34: =IF(S34="☑ Completed", "COMPLETED", "NOT STARTED") | U34: Review Notes for Day 7
A35: 7 | B35: 2026-09-06 | C35: 1 | D35: 1 | E35: Month 1 | F35: Python | G35: Control Flow | H35: if | I35: Master if | J35: 30 min | K35: 30 min | L35: Code/Implement if | M35: 15 min | N35: When would you use if instead of an alternative? | O35: 15 min | P35: Explain the logic of if out loud. | Q35: Build/Refine code | R35: - | S35: ☐ Not Started | T35: =IF(S35="☑ Completed", "COMPLETED", "NOT STARTED") | U35: Review Notes for Day 7
A36: 7 | B36: 2026-09-06 | C36: 1 | D36: 1 | E36: Month 1 | F36: Python | G36: Control Flow | H36: elif | I36: Master elif | J36: 30 min | K36: 30 min | L36: Code/Implement elif | M36: 15 min | N36: When would you use elif instead of an alternative? | O36: 15 min | P36: Explain the logic of elif out loud. | Q36: Build/Refine code | R36: - | S36: ☐ Not Started | T36: =IF(S36="☑ Completed", "COMPLETED", "NOT STARTED") | U36: Review Notes for Day 7
A37: 8 | B37: 2026-09-07 | C37: 2 | D37: 1 | E37: Month 1 | F37: Python | G37: Control Flow | H37: else | I37: Master else | J37: 45 min | K37: 45 min | L37: Code/Implement else | M37: 15 min | N37: When would you use else instead of an alternative? | O37: 15 min | P37: Explain the logic of else out loud. | Q37: Build/Refine code | R37: 5 | S37: ☐ Not Started | T37: =IF(S37="☑ Completed", "COMPLETED", "NOT STARTED") | U37: Review Notes for Day 8
A38: 8 | B38: 2026-09-07 | C38: 2 | D38: 1 | E38: Month 1 | F38: Python | G38: Control Flow | H38: Nested conditions | I38: Master Nested conditions | J38: 30 min | K38: 30 min | L38: Code/Implement Nested conditions | M38: 15 min | N38: When would you use Nested conditions instead of an alternative? | O38: 15 min | P38: Explain the logic of Nested conditions out loud. | Q38: Build/Refine code | R38: - | S38: ☐ Not Started | T38: =IF(S38="☑ Completed", "COMPLETED", "NOT STARTED") | U38: Review Notes for Day 8
A39: 8 | B39: 2026-09-07 | C39: 2 | D39: 1 | E39: Month 1 | F39: Python | G39: Control Flow | H39: for loop | I39: Master for loop | J39: 30 min | K39: 30 min | L39: Code/Implement for loop | M39: 15 min | N39: When would you use for loop instead of an alternative? | O39: 15 min | P39: Explain the logic of for loop out loud. | Q39: Build/Refine code | R39: - | S39: ☐ Not Started | T39: =IF(S39="☑ Completed", "COMPLETED", "NOT STARTED") | U39: Review Notes for Day 8
A40: 8 | B40: 2026-09-07 | C40: 2 | D40: 1 | E40: Month 1 | F40: Python | G40: Control Flow | H40: while loop | I40: Master while loop | J40: 30 min | K40: 30 min | L40: Code/Implement while loop | M40: 15 min | N40: When would you use while loop instead of an alternative? | O40: 15 min | P40: Explain the logic of while loop out loud. | Q40: Build/Refine code | R40: - | S40: ☐ Not Started | T40: =IF(S40="☑ Completed", "COMPLETED", "NOT STARTED") | U40: Review Notes for Day 8
...

Sheet ALL TOPICS CHECKLIST
A1: Subject | B1: Topic | C1: Subtopic | D1: Planned Day | E1: Planned Time | F1: Completion Checkbox | G1: Status | H1: Revision 1 (Day + 3) | I1: Rev 1 Done | J1: Revision 2 (Day + 7) | K1: Rev 2 Done | L1: Confidence (1-5)
A2: Python | B2: Setup | C2: Python installation | D2: Day 1 | E2: 45 min | F2: ☐ Not Started | G2: =IF(F2="☑ Completed", "COMPLETED", "NOT STARTED") | H2: Day 4 | I2: ☐ Not Started | J2: Day 8 | K2: ☐ Not Started
A3: Python | B3: Setup | C3: VS Code setup | D3: Day 1 | E3: 30 min | F3: ☐ Not Started | G3: =IF(F3="☑ Completed", "COMPLETED", "NOT STARTED") | H3: Day 4 | I3: ☐ Not Started | J3: Day 8 | K3: ☐ Not Started
A4: Python | B4: Setup | C4: Virtual environment | D4: Day 1 | E4: 30 min | F4: ☐ Not Started | G4: =IF(F4="☑ Completed", "COMPLETED", "NOT STARTED") | H4: Day 4 | I4: ☐ Not Started | J4: Day 8 | K4: ☐ Not Started
A5: Python | B5: Setup | C5: pip | D5: Day 1 | E5: 30 min | F5: ☐ Not Started | G5: =IF(F5="☑ Completed", "COMPLETED", "NOT STARTED") | H5: Day 4 | I5: ☐ Not Started | J5: Day 8 | K5: ☐ Not Started
A6: Python | B6: Setup | C6: requirements.txt | D6: Day 1 | E6: 30 min | F6: ☐ Not Started | G6: =IF(F6="☑ Completed", "COMPLETED", "NOT STARTED") | H6: Day 4 | I6: ☐ Not Started | J6: Day 8 | K6: ☐ Not Started
A7: Python | B7: Basics | C7: Python syntax | D7: Day 2 | E7: 45 min | F7: ☐ Not Started | G7: =IF(F7="☑ Completed", "COMPLETED", "NOT STARTED") | H7: Day 5 | I7: ☐ Not Started | J7: Day 9 | K7: ☐ Not Started
A8: Python | B8: Basics | C8: Variables | D8: Day 2 | E8: 30 min | F8: ☐ Not Started | G8: =IF(F8="☑ Completed", "COMPLETED", "NOT STARTED") | H8: Day 5 | I8: ☐ Not Started | J8: Day 9 | K8: ☐ Not Started
A9: Python | B9: Basics | C9: int | D9: Day 2 | E9: 30 min | F9: ☐ Not Started | G9: =IF(F9="☑ Completed", "COMPLETED", "NOT STARTED") | H9: Day 5 | I9: ☐ Not Started | J9: Day 9 | K9: ☐ Not Started
A10: Python | B10: Basics | C10: float | D10: Day 2 | E10: 30 min | F10: ☐ Not Started | G10: =IF(F10="☑ Completed", "COMPLETED", "NOT STARTED") | H10: Day 5 | I10: ☐ Not Started | J10: Day 9 | K10: ☐ Not Started
A11: Python | B11: Basics | C11: string | D11: Day 2 | E11: 30 min | F11: ☐ Not Started | G11: =IF(F11="☑ Completed", "COMPLETED", "NOT STARTED") | H11: Day 5 | I11: ☐ Not Started | J11: Day 9 | K11: ☐ Not Started
A12: Python | B12: Basics | C12: boolean | D12: Day 3 | E12: 45 min | F12: ☐ Not Started | G12: =IF(F12="☑ Completed", "COMPLETED", "NOT STARTED") | H12: Day 6 | I12: ☐ Not Started | J12: Day 10 | K12: ☐ Not Started
A13: Python | B13: Basics | C13: None | D13: Day 3 | E13: 30 min | F13: ☐ Not Started | G13: =IF(F13="☑ Completed", "COMPLETED", "NOT STARTED") | H13: Day 6 | I13: ☐ Not Started | J13: Day 10 | K13: ☐ Not Started
... A516: Mock Interviews & Revision | B516: Full AI/ML Revision | C516: Comprehensive Review Part 30 | D516: Day 120 | E516: 45 min | F516: ☐ Not Started | G516: =IF(F516="☑ Completed", "COMPLETED", "NOT STARTED") | H516: Day 123 | I516: ☐ Not Started | J516: Day 127 | K516: ☐ Not Started
